2024-03-14 18:25:09,837 INFO    StreamThr :1429 [internal.py:wandb_internal():90] W&B internal server running at pid: 1429, started at: 2024-03-14 18:25:09.836056
2024-03-14 18:25:09,841 DEBUG   HandlerThread:1429 [handler.py:handle_request():141] handle_request: status
2024-03-14 18:25:09,870 DEBUG   SenderThread:1429 [sender.py:send_request():316] send_request: status
2024-03-14 18:25:09,874 DEBUG   SenderThread:1429 [sender.py:send():302] send: header
2024-03-14 18:25:09,874 INFO    WriterThread:1429 [datastore.py:open_for_write():75] open: /root/wj/stess/wandb/run-20240314_182509-308zpuf1/run-308zpuf1.wandb
2024-03-14 18:25:09,874 DEBUG   SenderThread:1429 [sender.py:send():302] send: run
2024-03-14 18:25:11,127 ERROR   SenderThread:1429 [internal_api.py:execute():207] 404 response executing GraphQL.
2024-03-14 18:25:11,128 ERROR   SenderThread:1429 [internal_api.py:execute():208] {"errors":[{"message":"project not found","path":["upsertBucket"]}],"data":{"upsertBucket":null}}
2024-03-14 18:25:11,876 INFO    HandlerThread:1429 [handler.py:finish():810] shutting down handler
2024-03-14 18:25:11,878 INFO    WriterThread:1429 [datastore.py:close():279] close: /root/wj/stess/wandb/run-20240314_182509-308zpuf1/run-308zpuf1.wandb
2024-03-14 18:25:11,879 ERROR   StreamThr :1429 [internal.py:wandb_internal():165] Thread SenderThread:
Traceback (most recent call last):
  File "/root/miniconda3/envs/ess/lib/python3.10/site-packages/wandb/sdk/lib/retry.py", line 113, in __call__
    result = self._call_fn(*args, **kwargs)
  File "/root/miniconda3/envs/ess/lib/python3.10/site-packages/wandb/sdk/internal/internal_api.py", line 204, in execute
    return self.client.execute(*args, **kwargs)  # type: ignore
  File "/root/miniconda3/envs/ess/lib/python3.10/site-packages/wandb/vendor/gql-0.2.0/wandb_gql/client.py", line 52, in execute
    result = self._get_result(document, *args, **kwargs)
  File "/root/miniconda3/envs/ess/lib/python3.10/site-packages/wandb/vendor/gql-0.2.0/wandb_gql/client.py", line 60, in _get_result
    return self.transport.execute(document, *args, **kwargs)
  File "/root/miniconda3/envs/ess/lib/python3.10/site-packages/wandb/vendor/gql-0.2.0/wandb_gql/transport/requests.py", line 39, in execute
    request.raise_for_status()
  File "/root/miniconda3/envs/ess/lib/python3.10/site-packages/requests/models.py", line 1021, in raise_for_status
    raise HTTPError(http_error_msg, response=self)
requests.exceptions.HTTPError: 404 Client Error: Not Found for url: https://api.wandb.ai/graphql

During handling of the above exception, another exception occurred:

Traceback (most recent call last):
  File "/root/miniconda3/envs/ess/lib/python3.10/site-packages/wandb/apis/normalize.py", line 25, in wrapper
    return func(*args, **kwargs)
  File "/root/miniconda3/envs/ess/lib/python3.10/site-packages/wandb/sdk/internal/internal_api.py", line 1465, in upsert_run
    response = self.gql(
  File "/root/miniconda3/envs/ess/lib/python3.10/site-packages/wandb/sdk/lib/retry.py", line 129, in __call__
    retry_timedelta_triggered = check_retry_fn(e)
  File "/root/miniconda3/envs/ess/lib/python3.10/site-packages/wandb/util.py", line 942, in check_retry_fn
    return fallback_retry_fn(e)
  File "/root/miniconda3/envs/ess/lib/python3.10/site-packages/wandb/util.py", line 889, in no_retry_auth
    raise CommError("Permission denied, ask the project owner to grant you access")
wandb.errors.CommError: Permission denied, ask the project owner to grant you access

During handling of the above exception, another exception occurred:

Traceback (most recent call last):
  File "/root/miniconda3/envs/ess/lib/python3.10/site-packages/wandb/sdk/internal/internal_util.py", line 51, in run
    self._run()
  File "/root/miniconda3/envs/ess/lib/python3.10/site-packages/wandb/sdk/internal/internal_util.py", line 102, in _run
    self._process(record)
  File "/root/miniconda3/envs/ess/lib/python3.10/site-packages/wandb/sdk/internal/internal.py", line 310, in _process
    self._sm.send(record)
  File "/root/miniconda3/envs/ess/lib/python3.10/site-packages/wandb/sdk/internal/sender.py", line 304, in send
    send_handler(record)
  File "/root/miniconda3/envs/ess/lib/python3.10/site-packages/wandb/sdk/internal/sender.py", line 782, in send_run
    self._init_run(run, config_value_dict)
  File "/root/miniconda3/envs/ess/lib/python3.10/site-packages/wandb/sdk/internal/sender.py", line 808, in _init_run
    server_run, inserted, server_messages = self._api.upsert_run(
  File "/root/miniconda3/envs/ess/lib/python3.10/site-packages/wandb/apis/normalize.py", line 61, in wrapper
    raise CommError(message, err).with_traceback(sys.exc_info()[2])
  File "/root/miniconda3/envs/ess/lib/python3.10/site-packages/wandb/apis/normalize.py", line 25, in wrapper
    return func(*args, **kwargs)
  File "/root/miniconda3/envs/ess/lib/python3.10/site-packages/wandb/sdk/internal/internal_api.py", line 1465, in upsert_run
    response = self.gql(
  File "/root/miniconda3/envs/ess/lib/python3.10/site-packages/wandb/sdk/lib/retry.py", line 129, in __call__
    retry_timedelta_triggered = check_retry_fn(e)
  File "/root/miniconda3/envs/ess/lib/python3.10/site-packages/wandb/util.py", line 942, in check_retry_fn
    return fallback_retry_fn(e)
  File "/root/miniconda3/envs/ess/lib/python3.10/site-packages/wandb/util.py", line 889, in no_retry_auth
    raise CommError("Permission denied, ask the project owner to grant you access")
wandb.errors.CommError: Permission denied, ask the project owner to grant you access
